# 7.2 Promise

[🎦Review Call back hell and Promise](../6.-yi-bu-3/6.4-callback-hell-he-promise.md)

## 三种状态

1. pending
2. resolved 成功
3. rejected 失败

🔷 pending -&gt; resolved

🔷 pending -&gt; rejected

🔷 变化不可逆

## 状态的表现和变化

* 状态的表现
  * pending 状态: 不会触发then和catch
  * resolved 状态: 会触发后续的then回调函数
  * rejected 状态：会触发后续的catch回调函数

```javascript
const p1 = Promise.resolve(100);
console.log(p1); // resolved

p1.then(data => {
    console.log(data);
}).catch(err => { // won't trigger
    console.log("error1", err);
}); 
// 100
```

```javascript
const p2 = Promise.reject("err2");
console.log(p2); // rejected

p2.then(data => { // won't trigger
    console.log(data);
}).catch(err => { 
    console.log(err);
});
// err2
```

* 状态的变化

```javascript
const p1 = new Promise((resolve, reject) => {

});
console.log(p1); // Promise{<pending>}
```

```javascript
const p2 = new Promise((resolve, reject) => {
    setTimeout(() => {
        resolve();
    });
});
console.log(p2); // Promise{<pending>}
setTimeout(() => console.log("setTimeout: ", p2)); // resolved
```

打印出pending状态是因为定义p2之后立刻去打印p2, 此时resolve\(\)还没有被执行。

```javascript
const p3 = new Promise((resolve, reject) => {
    setTimeout(() => {
        reject();
    });
});
console.log(p3); // Promise{<pending>}
setTimeout(() => console.log("setTimeout: ", p3)); // rejected
```

## then 和 catch 对状态的影响

* then正常返回 resolved， 里面有报错则返回rejected

```javascript
const p1 = Promise.resolve().then(() => {
    return 100;
}) // p1 最终结果 resolved
// resolved 触发后续 then 回调
p1.then(() => {
    console.log("123"); // print 123
});

const p2 = Promise.resolve().then(() => {
    thorw new Error("then error 2");
}) // p2 最终结果 rejected
// rejected 触发后续 catch 回调
p2.then(() => {
    console.log("456"); // do not print
}).catch(err => {
    console.error("err100", err) // err100 then error 2
}); // catch完 状态为 resolved
```

* catch 正常返回 resolved， 里面有报错则返回rejected

```javascript
const p3 = Promise.rejected("my err").catch(err => {
    console.error(err)
}); // catch完 最终结果 resolved => 触发then 回调

p3.then(() => {
    console.log("then100"); // then100
});

const p4 = Promise.rejected("my err").catch(err => {
    throw new Error("catch error");
}) // p4 最终结果 rejected => 触发 catch 回调

p4.then(() => {
    console.log("then200"); // do not print
}).catch(err => {
    console.log("some err"); // some err
}); // 最终状态 resolved
```



